<?xml version="1.0"?>
<!-- Manipulator Chain -->
<robot xmlns:xacro="http://ros.org/wiki/xacro">

  <!-- Link 1 -->
  <link name="link1">
    <visual>
      <origin xyz="0 0 0.044" rpy="0 0 0"/>
      <geometry>
        <mesh filename="package://dynamixel_7dof_arm_description/meshes/link1_visual.stl" scale="0.001 0.001 0.001"/>
      </geometry>
      <material name="grey"/>
    </visual>

    <collision>
      <origin xyz="0 0 0.044" rpy="0 0 0"/>
      <geometry>
        <mesh filename="package://dynamixel_7dof_arm_description/meshes/link1_collision.stl" scale="0.001 0.001 0.001"/>
      </geometry>
    </collision>

    <inertial>
      <origin xyz="3.0876154e-04 0.0000000e+00 -1.2176461e-04" />
      <mass value="7.9119962e-02" />
      <inertia ixx="1.2505234e-05" ixy="0.0" ixz="-1.7855208e-07"
               iyy="2.1898364e-05" iyz="0.0"
               izz="1.9267361e-05" />
    </inertial>
  </link>

  <!-- Joint 1 -->
  <joint name="joint1" type="revolute">
    <parent link="link1"/>
    <child link="link2"/>
    <origin xyz="0.0 0.0 0.098" rpy="-pi/2 0 0"/>
    <axis xyz="0 0 1"/>
    <limit velocity="4.8" effort="1" lower="${-pi*0.9}" upper="${pi*0.9}" />
  </joint>

  <!--  Link 2 -->
  <link name="link2">
    <visual>
      <origin xyz="0 0 0" rpy="0 0 0"/>
      <geometry>
        <mesh filename="package://dynamixel_7dof_arm_description/meshes/link2_visual.stl" scale="0.001 0.001 0.001"/>
      </geometry>
      <material name="grey"/>
    </visual>

    <collision>
      <origin xyz="0 0 0" rpy="0 0 0"/>
      <geometry>
        <mesh filename="package://dynamixel_7dof_arm_description/meshes/link2_collision.stl" scale="0.001 0.001 0.001"/>
      </geometry>
    </collision>

    <inertial>
      <origin xyz="-3.0184870e-04 5.4043684e-04 ${0.018 + 2.9433464e-02}" />
      <mass value="9.8406837e-02" />
      <inertia ixx="3.4543422e-05" ixy="-1.6031095e-08" ixz="-3.8375155e-07"
               iyy="3.2689329e-05" iyz="2.8511935e-08"
               izz="1.8850320e-05" />
    </inertial>
  </link>

  <!--  Joint 2 -->
  <joint name="joint2" type="revolute">
    <parent link="link2"/>
    <child link="link3"/>
    <origin xyz="0 -0.126 0" rpy="pi/2 0 0"/>
    <axis xyz="0 0 1"/>
    <limit velocity="4.8" effort="1" lower="${-pi*0.57}" upper="${pi*0.5}" />
  </joint>

  <!--  Link 3 -->
  <link name="link3">
    <visual>
      <origin xyz="0 0 0" rpy="0 0 0"/>
      <geometry>
        <mesh filename="package://dynamixel_7dof_arm_description/meshes/link3_visual.stl" scale="0.001 0.001 0.001"/>
      </geometry>
      <material name="grey"/>
    </visual>

    <collision>
      <origin xyz="0 0 0" rpy="0 0 0"/>
      <geometry>
        <mesh filename="package://dynamixel_7dof_arm_description/meshes/link3_collision.stl" scale="0.001 0.001 0.001"/>
      </geometry>
    </collision>

    <inertial>
      <origin xyz="1.0308393e-02 3.7743363e-04 1.0170197e-01" />
      <mass value="1.3850917e-01" />
      <inertia ixx="3.3055381e-04" ixy="-9.7940978e-08" ixz="-3.8505711e-05"
               iyy="3.4290447e-04" iyz="-1.5717516e-06"
               izz="6.0346498e-05" />
    </inertial>
  </link>

  <!--  Joint 3 -->
  <joint name="joint3" type="revolute">
    <parent link="link3"/>
    <child link="link4"/>
    <origin xyz="0 0 0.054" rpy="-pi/2 0 0"/>
    <axis xyz="0 1 0"/>
    <limit velocity="4.8" effort="1" lower="${-pi*0.3}" upper="${pi*0.44}" />
  </joint>

  <!--  Link 4 -->
  <link name="link4">
    <visual>
      <origin xyz="0 0 0" rpy="0 0 0"/>
      <geometry>
        <mesh filename="package://dynamixel_7dof_arm_description/meshes/link4_visual.stl" scale="0.001 0.001 0.001"/>
      </geometry>
      <material name="grey"/>
    </visual>

    <collision>
      <origin xyz="0 0 0" rpy="0 0 0"/>
      <geometry>
        <mesh filename="package://dynamixel_7dof_arm_description/meshes/link4_collision.stl" scale="0.001 0.001 0.001"/>
      </geometry>
    </collision>

    <inertial>
      <origin xyz="9.0909590e-02 3.8929816e-04 2.2413279e-04" />
      <mass value="1.3274562e-01" />
      <inertia ixx="3.0654178e-05" ixy="-1.2764155e-06" ixz="-2.6874417e-07"
               iyy="2.4230292e-04" iyz="1.1559550e-08"
               izz="2.5155057e-04" />
    </inertial>
  </link>

  <!--  Joint 4 -->
  <joint name="joint4" type="revolute">
    <parent link="link4"/>
    <child link="link5"/>
    <origin xyz="0 -0.092 0" rpy="pi/2 0 0"/>
    <axis xyz="0 1 0"/>
    <limit velocity="4.8" effort="1" lower="${-pi*0.57}" upper="${pi*0.65}" />
  </joint>

  <!--  Link 5 -->
  <link name="link5">
    <visual>
      <origin xyz="0 0 0" rpy="0 0 0"/>
      <geometry>
        <mesh filename="package://dynamixel_7dof_arm_description/meshes/link5_visual.stl" scale="0.001 0.001 0.001"/>
      </geometry>
      <material name="grey"/>
    </visual>

    <collision>
      <origin xyz="0 0 0" rpy="0 0 0"/>
      <geometry>
        <mesh filename="package://dynamixel_7dof_arm_description/meshes/link5_collision.stl" scale="0.001 0.001 0.001"/>
      </geometry>
    </collision>

    <inertial>
      <origin xyz="9.0909590e-02 3.8929816e-04 2.2413279e-04" />
      <mass value="1.3274562e-01" />
      <inertia ixx="3.0654178e-05" ixy="-1.2764155e-06" ixz="-2.6874417e-07"
               iyy="2.4230292e-04" iyz="1.1559550e-08"
               izz="2.5155057e-04" />
    </inertial>
  </link>

  <!--  Joint 5 -->
  <joint name="joint5" type="revolute">
    <parent link="link5"/>
    <child link="link6"/>
    <origin xyz="0 0 0.0425" rpy="-pi/2 0 0"/>
    <axis xyz="0 1 0"/>
    <limit velocity="4.8" effort="1" lower="${-pi*0.57}" upper="${pi*0.65}" />
  </joint>

  <!--  Link 6 -->
  <link name="link6">
    <visual>
      <origin xyz="0 0 0" rpy="0 0 0"/>
      <geometry>
        <mesh filename="package://dynamixel_7dof_arm_description/meshes/link6_visual.stl" scale="0.001 0.001 0.001"/>
      </geometry>
      <material name="grey"/>
    </visual>

    <collision>
      <origin xyz="0 0 0" rpy="0 0 0"/>
      <geometry>
        <mesh filename="package://dynamixel_7dof_arm_description/meshes/link6_collision.stl" scale="0.001 0.001 0.001"/>
      </geometry>
    </collision>

    <inertial>
      <origin xyz="9.0909590e-02 3.8929816e-04 2.2413279e-04" />
      <mass value="1.3274562e-01" />
      <inertia ixx="3.0654178e-05" ixy="-1.2764155e-06" ixz="-2.6874417e-07"
               iyy="2.4230292e-04" iyz="1.1559550e-08"
               izz="2.5155057e-04" />
    </inertial>
  </link>

  <!--  Joint 6 -->
  <joint name="joint6" type="revolute">
    <parent link="link6"/>
    <child link="link7"/>
    <origin xyz="0 -0.062 0" rpy="pi/2 0 0"/>
    <axis xyz="0 1 0"/>
    <limit velocity="4.8" effort="1" lower="${-pi*0.57}" upper="${pi*0.65}" />
  </joint>

  <!--  Link 7 -->
  <link name="link7">
    <visual>
      <origin xyz="0 0 0" rpy="0 0 0"/>
      <geometry>
        <mesh filename="package://dynamixel_7dof_arm_description/meshes/link7_visual.stl" scale="0.001 0.001 0.001"/>
      </geometry>
      <material name="grey"/>
    </visual>

    <collision>
      <origin xyz="0 0 0" rpy="0 0 0"/>
      <geometry>
        <mesh filename="package://dynamixel_7dof_arm_description/meshes/link7_collision.stl" scale="0.001 0.001 0.001"/>
      </geometry>
    </collision>

    <inertial>
      <origin xyz="9.0909590e-02 3.8929816e-04 2.2413279e-04" />
      <mass value="1.3274562e-01" />
      <inertia ixx="3.0654178e-05" ixy="-1.2764155e-06" ixz="-2.6874417e-07"
               iyy="2.4230292e-04" iyz="1.1559550e-08"
               izz="2.5155057e-04" />
    </inertial>
  </link>

  <!--  Joint 7 -->
  <joint name="joint7" type="revolute">
    <parent link="link7"/>
    <child link="gripper"/>
    <origin xyz="0 0 0.036" rpy="-pi/2 0 0"/>
    <axis xyz="0 1 0"/>
    <limit velocity="4.8" effort="1" lower="${-pi*0.57}" upper="${pi*0.65}" />
  </joint>

  <!--  Gripper -->
  <link name="gripper">
    <visual>
      <origin xyz="0 0 0" rpy="0 0 0"/>
      <geometry>
        <mesh filename="package://dynamixel_7dof_arm_description/meshes/gripper_visual.stl" scale="0.001 0.001 0.001"/>
      </geometry>
      <material name="grey"/>
    </visual>

    <collision>
      <origin xyz="0 0 0" rpy="0 0 0"/>
      <geometry>
        <mesh filename="package://dynamixel_7dof_arm_description/meshes/gripper_collision.stl" scale="0.001 0.001 0.001"/>
      </geometry>
    </collision>

    <inertial>
      <origin xyz="4.4206755e-02 3.6839985e-07 8.9142216e-03" />
      <mass value="1.4327573e-01" />
      <inertia ixx="8.0870749e-05" ixy="0.0" ixz="-1.0157896e-06"
               iyy="7.5980465e-05" iyz="0.0"
               izz="9.3127351e-05" />
    </inertial>
  </link>

  <!--  Gripper joint 1 -->
  <joint name="gripper_joint1" type="prismatic">
    <parent link="gripper"/>
    <child link="finger_left"/>
    <origin xyz="0 0 0.016" rpy="pi pi 0"/>
    <axis xyz="0 0 -1"/>
    <limit velocity="4.8" effort="1" lower="-0.016" upper="0.016" />
  </joint>

  <!-- Left finger link -->
  <link name="finger_left">
    <visual>
      <origin xyz="0.0 0.0 0" rpy="0 0 0"/>
      <geometry>
        <mesh filename="package://dynamixel_7dof_arm_description/meshes/finger_visual.stl" scale="0.001 0.001 0.001"/>
      </geometry>
      <material name="grey"/>
    </visual>

    <collision>
      <origin xyz="0.0 0.0 0" rpy="0 0 0"/>
      <geometry>
        <mesh filename="package://dynamixel_7dof_arm_description/meshes/finger_collision.stl" scale="0.001 0.001 0.001"/>
      </geometry>
    </collision>

    <inertial>
      <origin xyz="0 0 0" />
      <mass value="1.0e-03" />
      <inertia ixx="1.0e-03" ixy="0.0" ixz="0.0"
               iyy="1.0e-03" iyz="0.0"
               izz="1.0e-03" />
    </inertial>
  </link>

  <!--  Gripper joint 2 -->
  <joint name="gripper_joint2" type="prismatic">
    <parent link="gripper"/>
    <child link="finger_right"/>
    <origin xyz="0 0 -0.016" rpy="0 0 pi"/>
    <axis xyz="0 0 1"/>
    <limit velocity="4.8" effort="1" lower="-0.016" upper="0.016" />
    <mimic joint="gripper" multiplier="1"/>
  </joint>

  <!-- Right finger link -->
  <link name="finger_right">
    <visual>
      <origin xyz="0 0 0" rpy="0 0 0"/>
      <geometry>
        <mesh filename="package://dynamixel_7dof_arm_description/meshes/finger_visual.stl" scale="0.001 0.001 0.001"/>
      </geometry>
      <material name="grey"/>
    </visual>

    <collision>
      <origin xyz="0 0 0" rpy="0 0 0"/>
      <geometry>
        <mesh filename="package://dynamixel_7dof_arm_description/meshes/finger_collision.stl" scale="0.001 0.001 0.001"/>
      </geometry>
    </collision>

    <inertial>
      <origin xyz="0 0 0" />
      <mass value="1.0e-03" />
      <inertia ixx="1.0e-03" ixy="0.0" ixz="0.0"
               iyy="1.0e-03" iyz="0.0"
               izz="1.0e-03" />
    </inertial>
  </link>

  <!-- end effector joint -->
  <joint name="end_effector_joint" type="fixed">
    <origin xyz="0 -0.0565 0" rpy="pi/2 0 0"/>
    <parent link="gripper"/>
    <child link="end_effector_link"/>
  </joint>

  <!-- end effector link -->
  <link name="end_effector_link">
    <visual>
      <origin xyz="0 0 0" rpy="0 0 0"/>
      <geometry>
        <box size="0.01 0.01 0.01" />
      </geometry>
      <material name="red"/>
     </visual>

    <inertial>
      <origin xyz="0 0 0" />
      <mass value="1.0e-03" />
      <inertia ixx="1.0e-03" ixy="0.0" ixz="0.0"
               iyy="1.0e-03" iyz="0.0"
               izz="1.0e-03" />
    </inertial>
  </link>

  <!-- Realsense Camera Joint Position -->
  <joint name="camera_joint" type="fixed">
    <axis xyz="0 1 0" />
    <origin xyz="0.070 0.032 0.052" rpy="0 0 0"/> 
    <parent link="link5"/>
    <child link="camera_link"/>
  </joint>

  <link name="camera_link"/>
  
</robot>
