<?xml version="1.0"?>
<!-- Manipulator Chain -->
<robot xmlns:xacro="http://ros.org/wiki/xacro">

  <!-- Link 1 -->
  <link name="link1">
    <visual>
      <origin xyz="0 0 0.044" rpy="0 0 0"/>
      <geometry>
        <mesh filename="package://dynamixel_7dof_arm_description/meshes/link1_visual.stl" scale="0.001 0.001 0.001"/>
      </geometry>
      <material name="grey"/>
    </visual>

    <collision>
      <origin xyz="0 0 0.044" rpy="0 0 0"/>
      <geometry>
        <mesh filename="package://dynamixel_7dof_arm_description/meshes/link1_collision.stl" scale="0.001 0.001 0.001"/>
      </geometry>
    </collision>

    <inertial>
      <origin xyz="0 0 0.044" />
      <mass value="1.65e-01" />
      <inertia ixx="9.7675421e-05" ixy="1.5076192e-06" ixz="-7.0306018e-05"
               iyy="1.9686152e-04" iyz="1.4556164e-06"
               izz="1.2605450e-04" />
    </inertial>
  </link>

  <!-- Joint 1 -->
  <joint name="joint1" type="revolute">
    <parent link="link1"/>
    <child link="link2"/>
    <origin xyz="0.0 0.0 0.098" rpy="${-pi*0.5} 0 0"/>
    <axis xyz="0 0 1"/>
    <limit velocity="${pi}" effort="1" lower="${-pi*0.9}" upper="${pi*0.9}" />
  </joint>

  <!--  Link 2 -->
  <link name="link2">
    <visual>
      <origin xyz="0 0 0" rpy="0 0 0"/>
      <geometry>
        <mesh filename="package://dynamixel_7dof_arm_description/meshes/link2_visual.stl" scale="0.001 0.001 0.001"/>
      </geometry>
      <material name="grey"/>
    </visual>

    <collision>
      <origin xyz="0 0 0" rpy="0 0 0"/>
      <geometry>
        <mesh filename="package://dynamixel_7dof_arm_description/meshes/link2_collision.stl" scale="0.001 0.001 0.001"/>
      </geometry>
    </collision>

    <inertial>
      <origin xyz="0 0 0" />
      <mass value="3.65360184e-01" />
      <inertia ixx="7.23925638e-04" ixy="-2.9538917e-06" ixz="4.0975813308e-06"
               iyy="4.921326352e-04" iyz="1.767767725e-04"
               izz="3.02730708e-04" />
    </inertial>
  </link>

  <!--  Joint 2 -->
  <joint name="joint2" type="revolute">
    <parent link="link2"/>
    <child link="link3"/>
    <origin xyz="0 -0.126 0" rpy="${pi*0.5} 0 0"/>
    <axis xyz="0 0 1"/>
    <limit velocity="${pi}" effort="1" lower="${-pi*0.25}" upper="${pi*0.5}" />
  </joint>

  <!--  Link 3 -->
  <link name="link3">
    <visual>
      <origin xyz="0 0 0" rpy="0 0 0"/>
      <geometry>
        <mesh filename="package://dynamixel_7dof_arm_description/meshes/link3_visual.stl" scale="0.001 0.001 0.001"/>
      </geometry>
      <material name="grey"/>
    </visual>

    <collision>
      <origin xyz="0 0 0" rpy="0 0 0"/>
      <geometry>
        <mesh filename="package://dynamixel_7dof_arm_description/meshes/link3_collision.stl" scale="0.001 0.001 0.001"/>
      </geometry>
    </collision>

    <inertial>
      <origin xyz="0 0 0" />
      <mass value="2.12396196e-01" />
      <inertia ixx="4.36697977e-04" ixy="1.5076192e-06" ixz="-8.98306422e-05"
               iyy="5.31846236e-04" iyz="1.4556164e-06"
               izz="1.5563934e-04" />
    </inertial>
  </link>

  <!--  Joint 3 -->
  <joint name="joint3" type="revolute">
    <parent link="link3"/>
    <child link="link4"/>
    <origin xyz="0 0 0.054" rpy="${-pi*0.5} 0 0"/>
    <axis xyz="0 1 0"/>
    <limit velocity="4.8" effort="1" lower="${-pi*0.3}" upper="${pi*0.44}" />
  </joint>

  <!--  Link 4 -->
  <link name="link4">
    <visual>
      <origin xyz="0 0 0" rpy="0 0 0"/>
      <geometry>
        <mesh filename="package://dynamixel_7dof_arm_description/meshes/link4_visual.stl" scale="0.001 0.001 0.001"/>
      </geometry>
      <material name="grey"/>
    </visual>

    <collision>
      <origin xyz="0 0 0" rpy="0 0 0"/>
      <geometry>
        <mesh filename="package://dynamixel_7dof_arm_description/meshes/link4_collision.stl" scale="0.001 0.001 0.001"/>
      </geometry>
    </collision>

    <inertial>
      <origin xyz="0 0 0" />
      <mass value="1.76006714e-01" />
      <inertia ixx="1.69380031e-04" ixy="-1.5076192e-06" ixz="-9.8692692e-09"
               iyy="4.53380742e-05" iyz="-1.8439349e-06"
               izz="1.52969543e-04" />
    </inertial>
  </link>

  <!--  Joint 4 -->
  <joint name="joint4" type="revolute">
    <parent link="link4"/>
    <child link="link5"/>
    <origin xyz="0 -0.092 0" rpy="${pi*0.5} 0 0"/>
    <axis xyz="0 1 0"/>
    <limit velocity="4.8" effort="1" lower="${-pi*0.57}" upper="${pi*0.65}" />
  </joint>

  <!--  Link 5 -->
  <link name="link5">
    <visual>
      <origin xyz="0 0 0" rpy="0 0 0"/>
      <geometry>
        <mesh filename="package://dynamixel_7dof_arm_description/meshes/link5_visual.stl" scale="0.001 0.001 0.001"/>
      </geometry>
      <material name="grey"/>
    </visual>

    <collision>
      <origin xyz="0 0 0" rpy="0 0 0"/>
      <geometry>
        <mesh filename="package://dynamixel_7dof_arm_description/meshes/link5_collision.stl" scale="0.001 0.001 0.001"/>
      </geometry>
    </collision>

    <inertial>
      <origin xyz="0 0 0" />
      <mass value="1.140236536e-01" />
      <inertia ixx="1.73149898e-04" ixy="6.4100516e-07" ixz="-5.44674084e-05"
               iyy="2.05741025e-04" iyz="5.6194478e-07"
               izz="6.4729774e-05" />
    </inertial>
  </link>

  <!--  Joint 5 -->
  <joint name="joint5" type="revolute">
    <parent link="link5"/>
    <child link="link6"/>
    <origin xyz="0 0 0.0425" rpy="${-pi*0.5} 0 0"/>
    <axis xyz="0 1 0"/>
    <limit velocity="4.8" effort="1" lower="${-pi*0.57}" upper="${pi*0.65}" />
  </joint>

  <!--  Link 6 -->
  <link name="link6">
    <visual>
      <origin xyz="0 0 0" rpy="0 0 0"/>
      <geometry>
        <mesh filename="package://dynamixel_7dof_arm_description/meshes/link6_visual.stl" scale="0.001 0.001 0.001"/>
      </geometry>
      <material name="grey"/>
    </visual>

    <collision>
      <origin xyz="0 0 0" rpy="0 0 0"/>
      <geometry>
        <mesh filename="package://dynamixel_7dof_arm_description/meshes/link6_collision.stl" scale="0.001 0.001 0.001"/>
      </geometry>
    </collision>

    <inertial>
      <origin xyz="0 0 0" />
      <mass value="8.76309701e-02" />
      <inertia ixx="5.25353043e-05" ixy="-6.4100516e-07" ixz="-5.5567317e-09"
               iyy="1.49092849e-05" iyz="-1.0653297e-06"
               izz="4.86901315e-05" />
    </inertial>
  </link>

  <!--  Joint 6 -->
  <joint name="joint6" type="revolute">
    <parent link="link6"/>
    <child link="link7"/>
    <origin xyz="0 -0.062 0" rpy="${pi*0.5} 0 0"/>
    <axis xyz="0 1 0"/>
    <limit velocity="4.8" effort="1" lower="${-pi*0.57}" upper="${pi*0.65}" />
  </joint>

  <!--  Link 7 -->
  <link name="link7">
    <visual>
      <origin xyz="0 0 0" rpy="0 0 0"/>
      <geometry>
        <mesh filename="package://dynamixel_7dof_arm_description/meshes/link7_visual.stl" scale="0.001 0.001 0.001"/>
      </geometry>
      <material name="grey"/>
    </visual>

    <collision>
      <origin xyz="0 0 0" rpy="0 0 0"/>
      <geometry>
        <mesh filename="package://dynamixel_7dof_arm_description/meshes/link7_collision.stl" scale="0.001 0.001 0.001"/>
      </geometry>
    </collision>

    <inertial>
      <origin xyz="0 0 0" />
      <mass value="9.3693466e-02" />
      <inertia ixx="5.2902474e-05" ixy="6.40951087082e-07" ixz="-2.4025384e-05"
               iyy="8.2881293e-05" iyz="5.6194478e-07"
               izz="4.61038615e-05" />
    </inertial>
  </link>

  <!--  Joint 7 -->
  <joint name="joint7" type="revolute">
    <parent link="link7"/>
    <child link="gripper"/>
    <origin xyz="0 0 0.036" rpy="${-pi*0.5} 0 0"/>
    <axis xyz="0 1 0"/>
    <limit velocity="4.8" effort="1" lower="${-pi*0.57}" upper="${pi*0.65}" />
  </joint>

  <!--  Gripper -->
  <link name="gripper">
    <visual>
      <origin xyz="0 0 0" rpy="0 0 0"/>
      <geometry>
        <mesh filename="package://dynamixel_7dof_arm_description/meshes/gripper_visual.stl" scale="0.001 0.001 0.001"/>
      </geometry>
      <material name="grey"/>
    </visual>

    <collision>
      <origin xyz="0 0 0" rpy="0 0 0"/>
      <geometry>
        <mesh filename="package://dynamixel_7dof_arm_description/meshes/gripper_collision.stl" scale="0.001 0.001 0.001"/>
      </geometry>
    </collision>

    <inertial>
      <origin xyz="0 0 0" />
      <mass value="1.175366352e-01" />
      <inertia ixx="6.087557e-05" ixy="-5.0302e-08" ixz="-2.027965366431884e-05"
               iyy="9.5134911e-05" iyz="5.61960245365e-07"
               izz="4.986382864e-05" />
    </inertial>
  </link>

  <!--  Gripper joint 1 -->
  <joint name="gripper_joint1" type="prismatic">
    <parent link="gripper"/>
    <child link="finger_left"/>
    <origin xyz="0 0 0.016" rpy="${pi} ${pi} 0"/>
    <axis xyz="0 0 -1"/>
    <limit velocity="4.8" effort="1" lower="-0.016" upper="0.016" />
  </joint>

  <!-- Left finger link -->
  <link name="finger_left">
    <visual>
      <origin xyz="0 0 0" rpy="0 0 0"/>
      <geometry>
        <mesh filename="package://dynamixel_7dof_arm_description/meshes/finger_visual.stl" scale="0.001 0.001 0.001"/>
      </geometry>
      <material name="grey"/>
    </visual>

    <collision>
      <origin xyz="0 0 0" rpy="0 0 0"/>
      <geometry>
        <mesh filename="package://dynamixel_7dof_arm_description/meshes/finger_collision.stl" scale="0.001 0.001 0.001"/>
      </geometry>
    </collision>

    <inertial>
      <origin xyz="0 0 0" />
      <mass value="1.5157383e-02" />
      <inertia ixx="2.1703323e-06" ixy="4.7785008e-08" ixz="1.9357889e-06"
               iyy="1.4304498e-05" iyz="1.8450264e-07"
               izz="1.3405196e-05" />
    </inertial>
  </link>

  <!--  Gripper joint 2 -->
  <joint name="gripper_joint2" type="prismatic">
    <parent link="gripper"/>
    <child link="finger_right"/>
    <origin xyz="0 0 -0.016" rpy="0 0 ${pi}"/>
    <axis xyz="0 0 1"/>
    <limit velocity="4.8" effort="1" lower="-0.016" upper="0.016" />
    <mimic joint="gripper" multiplier="1"/>
  </joint>

  <!-- Right finger link -->
  <link name="finger_right">
    <visual>
      <origin xyz="0 0 0" rpy="0 0 0"/>
      <geometry>
        <mesh filename="package://dynamixel_7dof_arm_description/meshes/finger_visual.stl" scale="0.001 0.001 0.001"/>
      </geometry>
      <material name="grey"/>
    </visual>

    <collision>
      <origin xyz="0 0 0" rpy="0 0 0"/>
      <geometry>
        <mesh filename="package://dynamixel_7dof_arm_description/meshes/finger_collision.stl" scale="0.001 0.001 0.001"/>
      </geometry>
    </collision>

    <inertial>
      <origin xyz="0 0 0" />
      <mass value="1.5157383e-02" />
      <inertia ixx="2.1703323e-06" ixy="4.7785008e-08" ixz="1.9357889e-06"
               iyy="1.4304498e-05" iyz="1.8450264e-07"
               izz="1.3405196e-05" />
    </inertial>
  </link>

  <!-- end effector joint -->
  <joint name="end_effector_joint" type="fixed">
    <origin xyz="0 -0.0565 0" rpy="${pi/2} 0 0"/>
    <parent link="gripper"/>
    <child link="end_effector_link"/>
  </joint>

  <!-- end effector link -->
  <link name="end_effector_link">
    <visual>
      <origin xyz="0 0 0" rpy="0 0 0"/>
      <geometry>
        <box size="0.01 0.01 0.01" />
      </geometry>
      <material name="red"/>
     </visual>

    <inertial>
      <origin xyz="0 0 0" />
      <mass value="1.0e-03" />
      <inertia ixx="1.0e-03" ixy="0.0" ixz="0.0"
               iyy="1.0e-03" iyz="0.0"
               izz="1.0e-03" />
    </inertial>
  </link>

  <!-- Realsense Camera Joint Position -->
  <joint name="camera_joint" type="fixed">
    <axis xyz="0 1 0" />
    <origin xyz="0.070 0.032 0.052" rpy="0 0 0"/> 
    <parent link="link5"/>
    <child link="camera_link"/>
  </joint>

  <link name="camera_link"/>
  
</robot>
